DEBUG:root:received {"dest":"n0","body":{"type":"init","node_id":"n0","node_ids":["n0","n1","n2","n3"],"msg_id":1},"src":"c3","id":3}
INFO:root:node n0 initialized
DEBUG:root:sending {"dest": "c3", "src": "n0", "body": {"msg_id": 1, "in_reply_to": 1, "type": "init_ok"}}
DEBUG:root:received {"dest":"n0","body":{"txn":[["append",7,1],["r",8,null],["r",9,null]],"type":"txn","msg_id":1},"src":"c10","id":11}
INFO:root:executing txn
DEBUG:root:c10-1: locking 7
DEBUG:root:c10-1: locking 8
DEBUG:root:c10-1: locking 9
DEBUG:root:c10-1: appending to 7: 1
DEBUG:root:c10-1: reading 8
DEBUG:root:c10-1: reading 9
DEBUG:root:c10-1: updating 7: [1]
DEBUG:root:sending {"dest": "c10", "src": "n0", "body": {"msg_id": 2, "in_reply_to": 1, "type": "txn_ok", "txn": [["append", 7, 1], ["r", 8, null], ["r", 9, null]]}}
ERROR:asyncio:Task exception was never retrieved
future: <Task finished name='Task-3' coro=<handle() done, defined at /home/peter/Documents/tf/lab4/cent.py:13> exception=TypeError("'types.SimpleNamespace' object is not callable")>
Traceback (most recent call last):
  File "/home/peter/Documents/tf/lab4/cent.py", line 36, in handle
    msg(node, type='txnReplication',txn=msg.body.txn, originalid=msg.body.msg_id)
TypeError: 'types.SimpleNamespace' object is not callable
DEBUG:root:received {"dest":"n0","body":{"txn":[["r",8,null]],"type":"txn","msg_id":2},"src":"c10","id":15}
INFO:root:executing txn
DEBUG:root:c10-2: locking 8
