DEBUG:root:received {"dest":"n3","body":{"type":"init","node_id":"n3","node_ids":["n1","n2","n3","n4","n5"],"msg_id":1},"src":"c1","id":1}
INFO:root:node n3 initialized
DEBUG:root:sending {"dest": "c1", "src": "n3", "body": {"msg_id": 1, "in_reply_to": 1, "type": "init_ok"}}
DEBUG:root:received {"dest":"n3","src":"n1","body":{"msg_id":3,"type":"AppendEntries","term":0,"prevIndex":0,"prevTerm":0,"entries":[[["pass",null],0]],"commit":0},"id":11}
DEBUG:root:sending {"dest": "n1", "src": "n3", "body": {"msg_id": 2, "in_reply_to": 3, "type": "AppendEntriesRes", "res": true, "term": 0, "next": 1, "commit": 0}}
DEBUG:root:received {"dest":"n3","body":{"key":0,"type":"read","msg_id":1},"src":"c14","id":25}
DEBUG:root:sending {"dest": "c14", "src": "n3", "body": {"msg_id": 3, "in_reply_to": 1, "type": "error", "code": 11, "text": "Not Leader"}}
DEBUG:root:received {"dest":"n3","src":"n1","body":{"msg_id":8,"type":"AppendEntries","term":0,"prevIndex":1,"prevTerm":[0,2],"entries":[["write",[0,3],0]],"commit":0},"id":35}
DEBUG:root:sending {"dest": "n1", "src": "n3", "body": {"msg_id": 4, "in_reply_to": 8, "type": "AppendEntriesRes", "res": false, "term": 0}}
DEBUG:root:received {"dest":"n3","src":"n1","body":{"msg_id":12,"type":"AppendEntries","term":0,"prevIndex":0,"prevTerm":0,"entries":[["write",[0,2],0],["write",[0,3],0]],"commit":0},"id":43}
DEBUG:root:sending {"dest": "n1", "src": "n3", "body": {"msg_id": 5, "in_reply_to": 12, "type": "AppendEntriesRes", "res": true, "term": 0, "next": 2, "commit": 0}}
DEBUG:root:received {"dest":"n3","src":"n1","body":{"msg_id":16,"type":"AppendEntries","term":0,"prevIndex":2,"prevTerm":[0,3],"entries":[["cas",[1,[3,3]],0]],"commit":0},"id":52}
ERROR:root:fatal exception in handler
Traceback (most recent call last):
  File "/home/peter/Documents/tf/lab3/raft.py", line 278, in handle
    a = log[msg.body.prevIndex]
IndexError: list index out of range

During handling of the above exception, another exception occurred:

Traceback (most recent call last):
  File "/home/peter/Documents/tf/lab3/ms.py", line 27, in exitOnError
    fn(*args)
  File "/home/peter/Documents/tf/lab3/raft.py", line 280, in handle
    buildString([ "280",log,msg.body.prevIndex,commitIndex,node_id])
  File "/home/peter/Documents/tf/lab3/raft.py", line 58, in buildString
    raise Exception(s)
Exception: 280
[(('pass', None), 0), ['write', [0, 3], 0]]
2
0
n3

