DEBUG:root:received {"dest":"n5","body":{"type":"init","node_id":"n5","node_ids":["n1","n2","n3","n4","n5"],"msg_id":1},"src":"c3","id":3}
INFO:root:node n5 initialized
DEBUG:root:sending {"dest": "c3", "src": "n5", "body": {"msg_id": 1, "in_reply_to": 1, "type": "init_ok"}}
DEBUG:root:received {"dest":"n5","src":"n1","body":{"msg_id":5,"type":"AppendEntries","term":0,"prevIndex":0,"prevTerm":0,"entries":[[["pass",null],0]],"commit":0},"id":14}
DEBUG:root:sending {"dest": "n1", "src": "n5", "body": {"msg_id": 2, "in_reply_to": 5, "type": "AppendEntriesRes", "res": true, "term": 0, "next": 1, "commit": 0}}
Exception in thread Thread-1:
Traceback (most recent call last):
  File "/usr/lib/python3.10/threading.py", line 1009, in _bootstrap_inner
    self.run()
  File "/usr/lib/python3.10/threading.py", line 1371, in run
    self.function(*self.args, **self.kwargs)
  File "/home/peter/Documents/tf/lab3/raft.py", line 59, in buildString
    raise Exception(s)
Exception: ('n1', 1651437581521731014)
('n2', 1651437581499935871)
('n3', 1651437581499935871)
('n4', 1651437581499935871)
('n5', 1651437581499935871)

DEBUG:root:received {"dest":"n5","body":{"key":0,"type":"read","msg_id":1},"src":"c18","id":38}
DEBUG:root:sending {"dest": "c18", "src": "n5", "body": {"msg_id": 3, "in_reply_to": 1, "type": "error", "code": 11, "text": "Not Leader"}}
DEBUG:root:received {"dest":"n5","body":{"key":1,"value":0,"type":"write","msg_id":1},"src":"c19","id":40}
DEBUG:root:sending {"dest": "c19", "src": "n5", "body": {"msg_id": 4, "in_reply_to": 1, "type": "error", "code": 11, "text": "Not Leader"}}
