DEBUG:root:received {"dest":"n3","body":{"type":"init","node_id":"n3","node_ids":["n1","n2","n3","n4","n5"],"msg_id":1},"src":"c0","id":0}
INFO:root:node n3 initialized
DEBUG:root:sending {"dest": "c0", "src": "n3", "body": {"msg_id": 1, "in_reply_to": 1, "type": "init_ok"}}
DEBUG:root:received {"dest":"n3","src":"n1","body":{"msg_id":3,"type":"AppendEntries","term":0,"prevIndex":0,"prevTerm":0,"entries":[["cas",[0,[2,0]],0]],"commit":0},"id":28}
DEBUG:root:sending {"dest": "n1", "src": "n3", "body": {"msg_id": 2, "in_reply_to": 3, "type": "AppendEntriesRes", "res": true, "term": 0, "next": 1, "commit": 0}}
DEBUG:root:received {"dest":"n3","src":"n1","body":{"msg_id":7,"type":"AppendEntries","term":0,"prevIndex":1,"prevTerm":[0,[2,0]],"entries":[["cas",[1,[3,1]],0]],"commit":0},"id":37}
ERROR:root:fatal exception in handler
Traceback (most recent call last):
  File "/home/peter/Documents/tf/lab3/ms.py", line 27, in exitOnError
    fn(*args)
  File "/home/peter/Documents/tf/lab3/raft.py", line 264, in handle
    elif log[msg.body.prevIndex][1]!=msg.body.prevTerm:
IndexError: list index out of range
