DEBUG:root:received {"dest":"n3","body":{"type":"init","node_id":"n3","node_ids":["n1","n2","n3","n4","n5"],"msg_id":1},"src":"c3","id":3}
INFO:root:node n3 initialized
DEBUG:root:sending {"dest": "c3", "src": "n3", "body": {"msg_id": 1, "in_reply_to": 1, "type": "init_ok"}}
DEBUG:root:received {"dest":"n3","src":"n1","body":{"msg_id":3,"type":"AppendEntries","term":0,"prevIndex":0,"prevTerm":0,"entries":[[["pass",null],0]],"commit":0},"id":11}
DEBUG:root:sending {"dest": "n1", "src": "n3", "body": {"msg_id": 2, "in_reply_to": 3, "type": "AppendEntriesRes", "res": true, "term": 0, "next": 1, "commit": 0}}
DEBUG:root:received {"dest":"n3","src":"n1","body":{"msg_id":7,"type":"AppendEntries","term":0,"prevIndex":0,"prevTerm":0,"entries":[["write",[1,2],0]],"commit":0},"id":34}
DEBUG:root:sending {"dest": "n1", "src": "n3", "body": {"msg_id": 3, "in_reply_to": 7, "type": "AppendEntriesRes", "res": true, "term": 0, "next": 0, "commit": 0}}
DEBUG:root:received {"dest":"n3","src":"n1","body":{"msg_id":11,"type":"AppendEntries","term":0,"prevIndex":-1,"prevTerm":[1,[4,3]],"entries":[[["pass",null],0],["write",[1,2],0],["cas",[1,[4,3]],0]],"commit":0},"id":43}
ERROR:root:fatal exception in handler
Traceback (most recent call last):
  File "/home/peter/Documents/tf/lab3/raft.py", line 278, in handle
    a = log[msg.body.prevIndex]
IndexError: list index out of range

During handling of the above exception, another exception occurred:

Traceback (most recent call last):
  File "/home/peter/Documents/tf/lab3/ms.py", line 27, in exitOnError
    fn(*args)
  File "/home/peter/Documents/tf/lab3/raft.py", line 280, in handle
    buildString([ "280",log,msg.body.prevIndex,commitIndex,node_id,msg.body.entries])
  File "/home/peter/Documents/tf/lab3/raft.py", line 58, in buildString
    raise Exception(s)
Exception: 280
[]
-1
0
n3
[[['pass', None], 0], ['write', [1, 2], 0], ['cas', [1, [4, 3]], 0]]

