DEBUG:root:received {"dest":"n2","body":{"type":"init","node_id":"n2","node_ids":["n1","n2","n3","n4","n5"],"msg_id":1},"src":"c1","id":1}
INFO:root:node n2 initialized
DEBUG:root:sending {"dest": "c1", "src": "n2", "body": {"msg_id": 1, "in_reply_to": 1, "type": "init_ok"}}
DEBUG:root:received {"dest":"n2","src":"n1","body":{"msg_id":2,"type":"AppendEntries","term":0,"prevIndex":0,"prevTerm":0,"entries":[[["pass",null],0]],"commit":0},"id":10}
DEBUG:root:sending {"dest": "n1", "src": "n2", "body": {"msg_id": 2, "in_reply_to": 2, "type": "AppendEntriesRes", "res": true, "term": 0, "next": 1, "commit": 0}}
DEBUG:root:received {"dest":"n2","src":"n1","body":{"msg_id":6,"type":"AppendEntries","term":0,"prevIndex":1,"prevTerm":[1,[3,0]],"entries":[["cas",[0,[0,3]],0]],"commit":0},"id":20}
ERROR:root:fatal exception in handler
Traceback (most recent call last):
  File "/home/peter/Documents/tf/lab3/raft.py", line 278, in handle
    a = log[msg.body.prevIndex]
IndexError: list index out of range

During handling of the above exception, another exception occurred:

Traceback (most recent call last):
  File "/home/peter/Documents/tf/lab3/ms.py", line 27, in exitOnError
    fn(*args)
  File "/home/peter/Documents/tf/lab3/raft.py", line 280, in handle
    buildString([ "280",log,msg.body.prevIndex,commitIndex,node_id])
  File "/home/peter/Documents/tf/lab3/raft.py", line 58, in buildString
    raise Exception(s)
Exception: 280
[(('pass', None), 0)]
1
0
n2

