DEBUG:root:received {"dest":"n4","body":{"type":"init","node_id":"n4","node_ids":["n1","n2","n3","n4","n5"],"msg_id":1},"src":"c1","id":0}
INFO:root:node n4 initialized
DEBUG:root:sending {"dest": "c1", "src": "n4", "body": {"msg_id": 1, "in_reply_to": 1, "type": "init_ok"}}
DEBUG:root:received {"dest":"n4","src":"n1","body":{"msg_id":5,"type":"AppendEntries","term":0,"prevIndex":0,"prevTerm":0,"entries":[[["pass",null],0]],"commit":0},"id":13}
DEBUG:root:sending {"dest": "n1", "src": "n4", "body": {"msg_id": 2, "in_reply_to": 5, "type": "AppendEntriesRes", "res": true, "term": 0, "next": 2, "commit": 0}}
DEBUG:root:received {"dest":"n4","src":"n1","body":{"msg_id":11,"type":"AppendEntries","term":0,"prevIndex":1,"prevTerm":0,"entries":[[["pass",null],0],[["pass",null],0]],"commit":0},"id":25}
ERROR:root:fatal exception in handler
Traceback (most recent call last):
  File "/home/peter/Documents/tf/lab3/ms.py", line 27, in exitOnError
    fn(*args)
  File "/home/peter/Documents/tf/lab3/raft.py", line 302, in handle
    if len(log)-1<=msg.body.prevIndex+i and log[msg.body.prevIndex+i][1]!=msg.body.entries[i-1][1]:
IndexError: list index out of range
