DEBUG:root:received {"dest":"n1","body":{"type":"init","node_id":"n1","node_ids":["n0","n1","n2","n3"],"msg_id":1},"src":"c0","id":0}
INFO:root:node n1 initialized
DEBUG:root:sending {"dest": "c0", "src": "n1", "body": {"msg_id": 1, "in_reply_to": 1, "type": "init_ok"}}
DEBUG:root:received {"dest":"n1","body":{"txn":[["append",9,2],["r",7,null],["append",9,3],["r",9,null]],"type":"txn","msg_id":1},"src":"c9","id":10}
INFO:root:executing txn
DEBUG:root:c9-1: locking 7
DEBUG:root:c9-1: locking 9
DEBUG:root:c9-1: appending to 9: 2
DEBUG:root:c9-1: reading 7
DEBUG:root:c9-1: appending to 9: 3
DEBUG:root:c9-1: reading 9
DEBUG:root:c9-1: updating 9: [2, 3]
DEBUG:root:sending {"dest": "c9", "src": "n1", "body": {"msg_id": 2, "in_reply_to": 1, "type": "txn_ok", "txn": [["append", 9, 2], ["r", 7, null], ["append", 9, 3], ["r", 9, [2, 3]]]}}
ERROR:asyncio:Task exception was never retrieved
future: <Task finished name='Task-3' coro=<handle() done, defined at /home/peter/Documents/tf/lab4/cent.py:13> exception=TypeError("'types.SimpleNamespace' object is not callable")>
Traceback (most recent call last):
  File "/home/peter/Documents/tf/lab4/cent.py", line 36, in handle
    msg(node, type='txnReplication',txn=msg.body.txn, originalid=msg.body.msg_id)
TypeError: 'types.SimpleNamespace' object is not callable
DEBUG:root:received {"dest":"n1","body":{"txn":[["append",8,3],["r",9,null]],"type":"txn","msg_id":2},"src":"c9","id":19}
INFO:root:executing txn
DEBUG:root:c9-2: locking 8
DEBUG:root:c9-2: locking 9
