DEBUG:root:received {"dest":"n4","body":{"type":"init","node_id":"n4","node_ids":["n1","n2","n3","n4","n5"],"msg_id":1},"src":"c1","id":1}
INFO:root:node n4 initialized
DEBUG:root:sending {"dest": "c1", "src": "n4", "body": {"msg_id": 1, "in_reply_to": 1, "type": "init_ok"}}
DEBUG:root:received {"dest":"n4","src":"n1","body":{"msg_id":4,"type":"AppendEntries","term":0,"prevIndex":0,"prevTerm":0,"entries":[[["pass",null],0]],"commit":0},"id":12}
DEBUG:root:sending {"dest": "n1", "src": "n4", "body": {"msg_id": 2, "in_reply_to": 4, "type": "AppendEntriesRes", "res": true, "term": 0, "next": 1, "commit": 0}}
DEBUG:root:received {"dest":"n4","src":"n1","body":{"msg_id":8,"type":"AppendEntries","term":0,"prevIndex":1,"prevTerm":[1,3],"entries":[["cas",[0,[3,2]],0]],"commit":0},"id":22}
DEBUG:root:sending {"dest": "n1", "src": "n4", "body": {"msg_id": 3, "in_reply_to": 8, "type": "AppendEntriesRes", "res": false, "term": 0}}
DEBUG:root:received {"dest":"n4","src":"n1","body":{"msg_id":13,"type":"AppendEntries","term":0,"prevIndex":0,"prevTerm":0,"entries":[["write",[1,3],0],["cas",[0,[3,2]],0]],"commit":0},"id":33}
DEBUG:root:sending {"dest": "n1", "src": "n4", "body": {"msg_id": 4, "in_reply_to": 13, "type": "AppendEntriesRes", "res": true, "term": 0, "next": 2, "commit": 0}}
DEBUG:root:received {"dest":"n4","src":"n1","body":{"msg_id":16,"type":"AppendEntries","term":0,"prevIndex":2,"prevTerm":[0,[3,2]],"entries":[["cas",[1,[1,1]],0]],"commit":0},"id":39}
ERROR:root:fatal exception in handler
Traceback (most recent call last):
  File "/home/peter/Documents/tf/lab3/ms.py", line 27, in exitOnError
    fn(*args)
  File "/home/peter/Documents/tf/lab3/raft.py", line 267, in handle
    elif log[msg.body.prevIndex][1]!=msg.body.prevTerm:
IndexError: list index out of range
